File: DATA/Avg_Stress_Strain_Overture_TPU.csv
Strain,Stress (MPa)
0,0
0.0003368,0.052407184
0.000703467,0.108255928
0.001070133,0.156891235
0.0014368,0.202375349
0.001803467,0.247157738
0.002170133,0.2915659
0.0025368,0.334592489
0.002903467,0.376962212
0.003270133,0.418570797
0.0036368,0.459108801
0.004003467,0.499891279
0.004370133,0.5405373
0.0047368,0.579505882
0.005103467,0.61942001
0.005470133,0.656833029
0.0058368,0.697174126
0.006203467,0.734311689
0.006570133,0.771870112
0.0069368,0.81061103
0.007303467,0.847428389
0.007670133,0.883123411
0.0080368,0.920717971
0.008403467,0.957069701
0.008770133,0.992606517
0.0091368,1.028465653
0.009503467,1.0638625
0.009870133,1.099373423
0.0102368,1.133791385
0.010603467,1.169079751
0.010970133,1.203262131
0.0113368,1.2381767
0.011703467,1.271912737
0.012070133,1.304857417
0.0124368,1.3394288
0.012803467,1.371544205
0.013170133,1.404817329
0.0135368,1.438268606
0.013903467,1.470027214
0.014270133,1.503260943
0.0146368,1.534830563
0.015003467,1.568070343
0.015370133,1.599862332
0.0157368,1.631180318
0.016103467,1.660553025
0.016470133,1.692529624
0.0168368,1.723781218
0.017203467,1.75407911
0.017570133,1.78362399
0.0179368,1.815064779
0.018303467,1.844045475
0.018670133,1.873311752
0.0190368,1.903879934
0.019403467,1.931724606
0.019770133,1.961602246
0.0201368,1.990509258
0.020503467,2.020208553
0.020870133,2.047863649
0.0212368,2.075667126
0.021603467,2.104142687
0.021970133,2.131193538
0.0223368,2.159382476
0.022703467,2.186419079
0.023070133,2.213344038
0.0234368,2.239939586
0.023803467,2.266534494
0.024170133,2.293423172
0.0245368,2.320186304
0.024903467,2.345822971
0.025270133,2.372032871
0.0256368,2.39738986
0.026003467,2.423824514
0.026370133,2.449304618
0.0267368,2.473980685
0.027103467,2.500157023
0.027470133,2.523900475
0.0278368,2.548503902
0.028203467,2.573199813
0.028570133,2.596848258
0.0289368,2.622318789
0.029303467,2.6460525
0.029670133,2.670919036
0.0300368,2.694452878
0.030403467,2.716789733
0.030770133,2.741075318
0.0311368,2.76450307
0.031503467,2.786777679
0.031870133,2.809921885
0.0322368,2.832817231
0.032603467,2.855940613
0.032970133,2.878891203
0.0333368,2.900607646
0.033703467,2.923349666
0.034070133,2.945330507
0.0344368,2.967154238
0.034803467,2.988415863
0.035170133,3.010182713
0.0355368,3.032708983
0.035903467,3.052945971
0.036270133,3.074724309
0.0366368,3.095765368
0.037003467,3.116729523
0.037370133,3.138371781
0.0377368,3.15811752
0.038103467,3.179036902
0.038470133,3.199856815
0.0388368,3.220294892
0.039203467,3.240353374
0.039570133,3.260305923
0.0399368,3.280237321
0.040303467,3.300586005
0.040670133,3.320055391
0.0410368,3.340150238
0.041403467,3.359552608
0.041770133,3.378664098
0.0421368,3.39758718
0.042503467,3.416625045
0.042870133,3.436292571
0.0432368,3.454515844
0.043603467,3.475261732
0.043970133,3.492110132
0.0443368,3.511946459
0.044703467,3.530331065
0.045070133,3.548634681
0.0454368,3.567699284
0.045803467,3.585707665
0.046170133,3.603316169
0.0465368,3.621386251
0.046903467,3.639229087
0.047270133,3.657800949
0.0476368,3.675138178
0.048003467,3.692879947
0.048370133,3.7105766
0.0487368,3.727201375
0.049103467,3.744828477
0.049470133,3.763166273
0.0498368,3.779340935
0.050203467,3.797442921
0.050570133,3.813012824
0.0509368,3.831040638
0.051303467,3.848344516
0.051670133,3.864271394
0.0520368,3.882418776
0.052403467,3.899005221
0.052770133,3.914797349
0.0531368,3.931510322
0.053503467,3.947584915
0.053870133,3.965414331
0.0542368,3.980547234
0.054603467,3.997043905
0.054970133,4.01302971
0.0553368,4.028256702
0.055703467,4.044490557
0.056070133,4.060657491
0.0564368,4.076071991
0.056803467,4.092274385
0.057170133,4.107810142
0.0575368,4.123793311
0.057903467,4.138653376
0.058270133,4.154427614
0.0586368,4.169478794
0.059003467,4.184405218
0.059370133,4.200159721
0.0597368,4.215102452
0.060103467,4.230459862
0.060470133,4.24582558
0.0608368,4.26045849
0.061203467,4.276271175
0.061570133,4.29026751
0.0619368,4.305375503
0.062303467,4.319568476
0.062670133,4.333617083
0.0630368,4.348374345
0.063403467,4.362653587
0.063770133,4.377660309
0.0641368,4.391013448
0.064503467,4.404731643
0.064870133,4.419613473
0.0652368,4.434965024
0.065603467,4.448179916
0.065970133,4.462855457
0.0663368,4.476207818
0.066703467,4.490971186
0.067070133,4.503614741
0.0674368,4.518226244
0.067803467,4.531664205
0.068170133,4.545460764
0.0685368,4.559730216
0.068903467,4.573336616
0.069270133,4.586705773
0.0696368,4.599992468
0.070003467,4.612861319
0.070370133,4.627280227
0.0707368,4.639564285
0.071103467,4.653485208
0.071470133,4.666812441
0.0718368,4.679730816
0.072203467,4.693255002
0.072570133,4.705422399
0.0729368,4.718743868
0.073303467,4.731617835
0.073670133,4.743067204
0.0740368,4.757665173
0.074403467,4.770355164
0.074770133,4.782442193
0.0751368,4.795837183
0.075503467,4.807069769
0.075870133,4.820817452
0.0762368,4.832855547
0.076603467,4.845612479
0.076970133,4.857824573
0.0773368,4.869178503
0.077703467,4.882049398
0.078070133,4.894847642
0.0784368,4.907330576
0.078803467,4.919325838
0.079170133,4.930910229
0.0795368,4.943817159
0.079903467,4.956679354
0.080270133,4.967125483
0.0806368,4.979717038
0.081003467,4.991500075
0.081370133,5.002750344
0.0817368,5.015382803
0.082103467,5.026742912
0.082470133,5.039246036
0.0828368,5.04884833
0.083203467,5.062106594
0.083570133,5.072767353
0.0839368,5.084605487
0.084303467,5.096312765
0.084670133,5.105835938
0.0850368,5.118768958
0.085403467,5.130175978
0.085770133,5.140732133
0.0861368,5.1522649
0.086503467,5.163484584
0.086870133,5.174521772
0.0872368,5.186440214
0.087603467,5.19639105
0.087970133,5.20825279
0.0883368,5.218532543
0.088703467,5.229331837
0.089070133,5.240437689
0.0894368,5.251484587
0.089803467,5.262789991
0.090170133,5.273058092
0.0905368,5.283901372
0.090903467,5.294897026
0.091270133,5.30524874
0.0916368,5.316512263
0.092003467,5.326332709
0.092370133,5.337705716
0.0927368,5.347926585
0.093103467,5.358436949
0.093470133,5.369391411
0.0938368,5.379074298
0.094203467,5.389391602
0.094570133,5.400828573
0.0949368,5.410833843
0.095303467,5.421889411
0.095670133,5.431190211
0.0960368,5.440978314
0.096403467,5.452360738
0.096770133,5.462059942
0.0971368,5.471899348
0.097503467,5.482151979
0.097870133,5.491914409
0.0982368,5.502806462
0.098603467,5.511981421
0.098970133,5.522524703
0.0993368,5.532058915
0.099703467,5.541241477
0.100070133,5.552538075
0.1004368,5.561071528
0.100803467,5.571541123
0.101170133,5.580443051
0.1015368,5.591102688
0.101903467,5.600518209
0.102270133,5.610239116
0.1026368,5.619558729
0.103003467,5.629079371
0.103370133,5.638479806
0.1037368,5.649555941
0.104103467,5.657891168
0.104470133,5.667756964
0.1048368,5.677186021
0.105203467,5.686493646
0.105570133,5.696413746
0.1059368,5.704887834
0.106303467,5.714896088
0.106670133,5.723825747
0.1070368,5.732851338
0.107403467,5.74357894
0.107770133,5.753453388
0.1081368,5.762069831
0.108503467,5.771506458
0.108870133,5.78041424
0.1092368,5.79004859
0.109603467,5.799189139
0.109970133,5.80887036
0.1103368,5.817144442
0.110703467,5.826521911
0.111070133,5.835954599
0.1114368,5.84397462
0.111803467,5.854337599
0.112170133,5.863235513
0.1125368,5.871102552
0.112903467,5.880111554
0.113270133,5.889270317
0.1136368,5.897884377
0.114003467,5.907121949
0.114370133,5.9161376
0.1147368,5.924737402
0.115103467,5.933224705
0.115470133,5.942336993
0.1158368,5.950965654
0.116203467,5.959235859
0.116570133,5.968990079
0.1169368,5.976649996
0.117303467,5.986149718
0.117670133,5.99435049
0.1180368,6.002462756
0.118403467,6.010683006
0.118770133,6.019709879
0.1191368,6.02795156
0.119503467,6.036886607
0.119870133,6.045015731
0.1202368,6.053897381
0.120603467,6.061945263
0.120970133,6.070564026
0.1213368,6.078084598
0.121703467,6.087231081
0.122070133,6.095690939
0.1224368,6.102754075
0.122803467,6.111634163
0.123170133,6.119783771
0.1235368,6.128393685
0.123903467,6.137348598
0.124270133,6.145162351
0.1246368,6.153063058
0.125003467,6.161446896
0.125370133,6.168442761
0.1257368,6.176704078
0.126103467,6.185812201
0.126470133,6.193637425
0.1268368,6.20134952
0.127203467,6.208958638
0.127570133,6.21735482
0.1279368,6.225484336
0.128303467,6.233533461
0.128670133,6.241341906
0.1290368,6.250772794
0.129403467,6.257811082
0.129770133,6.265170293
0.1301368,6.272289363
0.130503467,6.280925027
0.130870133,6.289482047
0.1312368,6.296953327
0.131603467,6.304451884
0.131970133,6.312127586
0.1323368,6.319892613
0.132703467,6.328434162
0.133070133,6.336843078
0.1334368,6.343241003
0.133803467,6.352069939
0.134170133,6.358799017
0.1345368,6.365832308
0.134903467,6.373640167
0.135270133,6.381280302
0.1356368,6.388760428
0.136003467,6.39615598
0.136370133,6.404553004
0.1367368,6.411189277
0.137103467,6.418659629
0.137470133,6.425696397
0.1378368,6.433972487
0.138203467,6.439702283
0.138570133,6.448743255
0.1389368,6.455849159
0.139303467,6.462636903
0.139670133,6.470433327
0.1400368,6.477608132
0.140403467,6.484058075
0.140770133,6.491215216
0.1411368,6.498644141
0.141503467,6.505820465
0.141870133,6.511998674
0.1422368,6.520804467
0.142603467,6.526761518
0.142970133,6.533748086
0.1433368,6.53992765
0.143703467,6.548321148
0.144070133,6.555016488
0.1444368,6.56149161
0.144803467,6.568736428
0.145170133,6.575784874
0.1455368,6.582476435
0.145903467,6.589405561
0.146270133,6.596011196
0.1466368,6.602748118
0.147003467,6.610094782
0.147370133,6.615405202
0.1477368,6.622993385
0.148103467,6.630570727
0.148470133,6.635909258
0.1488368,6.64297782
0.149203467,6.650469393
0.149570133,6.657178254
0.1499368,6.664012771
0.150303467,6.671545705
0.150670133,6.677000746
0.1510368,6.683141074
0.151403467,6.690731707
0.151770133,6.696907556
0.1521368,6.703391405
0.152503467,6.710114826
0.152870133,6.716381581
0.1532368,6.722827846
0.153603467,6.72952508
0.153970133,6.735266036
0.1543368,6.741980907
0.154703467,6.747862837
0.155070133,6.754480627
0.1554368,6.761088656
0.155803467,6.767374064
0.156170133,6.774587852
0.1565368,6.779616621
0.156903467,6.786252524
0.157270133,6.791906845
0.1576368,6.799038141
0.158003467,6.804967348
0.158370133,6.809150456
0.1587368,6.815952713
0.159103467,6.822360752
0.159470133,6.82798206
0.1598368,6.83330126
0.160203467,6.839803076
0.160570133,6.846309755
0.1609368,6.852060439
0.161303467,6.858229213
0.161670133,6.864066742
0.1620368,6.86947785
0.162403467,6.876432963
0.162770133,6.880963917
0.1631368,6.888475248
0.163503467,6.893780854
0.163870133,6.900040881
0.1642368,6.905581821
0.164603467,6.911647293
0.164970133,6.917724778
0.1653368,6.924140938
0.165703467,6.929796427
0.166070133,6.936383993
0.1664368,6.941076641
0.166803467,6.947211124
0.167170133,6.952965062
0.1675368,6.958734593
0.167903467,6.965011587
0.168270133,6.970278045
0.1686368,6.976426957
0.169003467,6.982431788
0.169370133,6.988584607
0.1697368,6.994160341
0.170103467,7.000409902
0.170470133,7.005004834
0.1708368,7.011391833
0.171203467,7.017117297
0.171570133,7.02344528
0.1719368,7.029889162
0.172303467,7.035211377
0.172670133,7.040786988
0.1730368,7.046824532
0.173403467,7.05219151
0.173770133,7.058453968
0.1741368,7.064590529
0.174503467,7.070735342
0.174870133,7.07520991
0.1752368,7.081876082
0.175603467,7.087310479
0.175970133,7.093256874
0.1763368,7.098139732
0.176703467,7.10475601
0.177070133,7.111199944
0.1774368,7.116463795
0.177803467,7.122059791
0.178170133,7.127676435
0.1785368,7.133023685
0.178903467,7.139642924
0.179270133,7.144582255
0.1796368,7.151853931
0.180003467,7.157131679
0.180370133,7.162545291
0.1807368,7.168550826
0.181103467,7.173459686
0.181470133,7.179275526
0.1818368,7.183965604
0.182203467,7.190844431
0.182570133,7.196669995
0.1829368,7.202825097
0.183303467,7.208432839
0.183670133,7.212902241
0.1840368,7.219110601
0.184403467,7.224091158
0.184770133,7.229487184
0.1851368,7.235890658
0.185503467,7.240308449
0.185870133,7.245970258
0.1862368,7.252153581
0.186603467,7.25603762
0.186970133,7.262057871
0.1873368,7.267575859
0.187703467,7.273290965
0.188070133,7.278388049
0.1884368,7.283891894
0.188803467,7.288402805
0.189170133,7.292606124
0.1895368,7.298208088
0.189903467,7.303605393
0.190270133,7.308875141
0.1906368,7.314366136
0.191003467,7.320257153
0.191370133,7.324678552
0.1917368,7.32932009
0.192103467,7.334313539
0.192470133,7.340400958
0.1928368,7.345523861
0.193203467,7.349767149
0.193570133,7.355809048
0.1939368,7.360534248
0.194303467,7.366007801
0.194670133,7.370348293
0.1950368,7.375650958
0.195403467,7.380205006
0.195770133,7.385378692
0.1961368,7.390281489
0.196503467,7.395437362
0.196870133,7.399941462
0.1972368,7.406077475
0.197603467,7.409517354
0.197970133,7.415882091
0.1983368,7.421569049
0.198703467,7.424532224
0.199070133,7.431149215
0.1994368,7.434017188
0.199803467,7.441229183
0.200170133,7.44402565
0.2005368,7.449730308
0.200903467,7.455082418
0.201270133,7.459150118
0.2016368,7.46451705
0.202003467,7.47038251
0.202370133,7.473954946
0.2027368,7.479092153
0.203103467,7.483001189
0.203470133,7.489022999
0.2038368,7.493416837
0.204203467,7.498494562
0.204570133,7.504656804
0.2049368,7.508074537
0.205303467,7.513192825
0.205670133,7.518046155
0.2060368,7.522583266
0.206403467,7.526452839
0.206770133,7.530034365
0.2071368,7.536268047
0.207503467,7.541446475
0.207870133,7.545626055
0.2082368,7.55136407
0.208603467,7.554864372
0.208970133,7.560541655
0.2093368,7.563611377
0.209703467,7.568364047
0.210070133,7.572458326
0.2104368,7.576520278
0.210803467,7.581636625
0.211170133,7.585691608
0.2115368,7.589568634
0.211903467,7.594317044
0.212270133,7.598951469
0.2126368,7.602799349
0.213003467,7.606664538
0.213370133,7.611608102
0.2137368,7.61631618
0.214103467,7.61935476
0.214470133,7.624653369
0.2148368,7.628512085
0.215203467,7.631112826
0.215570133,7.636989373
0.2159368,7.640177047
0.216303467,7.644375152
0.216670133,7.649057924
0.2170368,7.652397491
0.217403467,7.656460226
0.217770133,7.660905607
0.2181368,7.663855814
0.218503467,7.668537572
0.218870133,7.67194244
0.2192368,7.676827314
0.219603467,7.679752434
0.219970133,7.684898507
0.2203368,7.689163043
0.220703467,7.692135768
0.221070133,7.696803191
0.2214368,7.700330982
0.221803467,7.705240885
0.222170133,7.708233159
0.2225368,7.712563522
0.222903467,7.716925064
0.223270133,7.720033498
0.2236368,7.72515778
0.224003467,7.728192127
0.224370133,7.731953817
0.2247368,7.736755445
0.225103467,7.740303209
0.225470133,7.743698448
0.2258368,7.747849537
0.226203467,7.751691636
0.226570133,7.755356708
0.2269368,7.758572249
0.227303467,7.762649274
0.227670133,7.767368716
0.2280368,7.770570776
0.228403467,7.774261371
0.228770133,7.777343333
0.2291368,7.782097035
0.229503467,7.785617477
0.229870133,7.789168294
0.2302368,7.793757772
0.230603467,7.796610547
0.230970133,7.800391914
0.2313368,7.804310232
0.231703467,7.808758827
0.232070133,7.811987315
0.2324368,7.815624328
0.232803467,7.818662744
0.233170133,7.822428607
0.2335368,7.826958214
0.233903467,7.82993495
0.234270133,7.833045684
0.2346368,7.837364802
0.235003467,7.840870494
0.235370133,7.845884171
0.2357368,7.847782045
0.236103467,7.851564507
0.236470133,7.855718333
0.2368368,7.859004589
0.237203467,7.862147526
0.237570133,7.866783158
0.2379368,7.870170783
0.238303467,7.874570851
0.238670133,7.878496822
0.2390368,7.881529151
0.239403467,7.885549803
0.239770133,7.889172687
0.2401368,7.893789226
0.240503467,7.896827779
0.240870133,7.900446404
0.2412368,7.904698042
0.241603467,7.907235858
0.241970133,7.910621005
0.2423368,7.916010264
0.242703467,7.917839918
0.243070133,7.923094899
0.2434368,7.924868061
0.243803467,7.929591009
0.244170133,7.933179124
0.2445368,7.937593967
0.244903467,7.940127792
0.245270133,7.943540051
0.2456368,7.948754576
0.246003467,7.950385036
0.246370133,7.954324758
0.2467368,7.957696212
0.247103467,7.962006112
0.247470133,7.965602865
0.2478368,7.968914143
0.248203467,7.97246584
0.248570133,7.976097629
0.2489368,7.97865577
0.249303467,7.983794387
0.249670133,7.986485663
0.2500368,7.989699519
0.250403467,7.993594493
0.250770133,7.996424106
0.2511368,8.001444882
0.251503467,8.003255761
0.251870133,8.007646578
0.2522368,8.011401995
0.252603467,8.013901866
0.252970133,8.018034778
0.2533368,8.020341768
0.253703467,8.025210127
0.254070133,8.028373077
0.2544368,8.03155021
0.254803467,8.035327355
0.255170133,8.039110358
0.2555368,8.041155344
0.255903467,8.045773746
0.256270133,8.04823888
0.2566368,8.051701728
0.257003467,8.055477338
0.257370133,8.058261224
0.2577368,8.062341063
0.258103467,8.065582492
0.258470133,8.069490803
0.2588368,8.072423697
0.259203467,8.075661123
0.259570133,8.07944482
0.2599368,8.082593741
0.260303467,8.087190534
0.260670133,8.089266709
0.2610368,8.094193674
0.261403467,8.097079838
0.261770133,8.09938647
0.2621368,8.10358297
0.262503467,8.106887067
0.262870133,8.108764328
0.2632368,8.113873521
0.263603467,8.115863604
0.263970133,8.119958042
0.2643368,8.123071832
0.264703467,8.126534149
0.265070133,8.130442088
0.2654368,8.132123512
0.265803467,8.136787453
0.266170133,8.140107079
0.2665368,8.142619126
0.266903467,8.147535689
0.267270133,8.15012943
0.2676368,8.153437685
0.268003467,8.155636183
0.268370133,8.159087753
0.2687368,8.162676943
0.269103467,8.166322351
0.269470133,8.169827651
0.2698368,8.172384233
0.270203467,8.176315342
0.270570133,8.179795885
0.2709368,8.182985539
0.271303467,8.185821955
0.271670133,8.187643542
0.2720368,8.191202263
0.272403467,8.194821038
0.272770133,8.198158825
0.2731368,8.200641945
0.273503467,8.204367187
0.273870133,8.207451382
0.2742368,8.210724037
0.274603467,8.213083081
0.274970133,8.216221841
0.2753368,8.220142482
0.275703467,8.222591688
0.276070133,8.22639291
0.2764368,8.227970746
0.276803467,8.232074613
0.277170133,8.234314055
0.2775368,8.238655016
0.277903467,8.241014566
0.278270133,8.243502583
0.2786368,8.246249952
0.279003467,8.249229295
0.279370133,8.253040507
0.2797368,8.255136329
0.280103467,8.25852122
0.280470133,8.261728558
0.2808368,8.263876143
0.281203467,8.266828358
0.281570133,8.270591675
0.2819368,8.273370588
0.282303467,8.275770792
0.282670133,8.27894287
0.2830368,8.282601997
0.283403467,8.284946796
0.283770133,8.28779246
0.2841368,8.291559351
0.284503467,8.294150059
0.284870133,8.29608634
0.2852368,8.299516994
0.285603467,8.302268547
0.285970133,8.305492379
0.2863368,8.307777833
0.286703467,8.311010209
0.287070133,8.313728795
0.2874368,8.315913451
0.287803467,8.319660249
0.288170133,8.321798883
0.2885368,8.325788535
0.288903467,8.327412074
0.289270133,8.330587528
0.2896368,8.332905494
0.290003467,8.336884577
0.290370133,8.338440862
0.2907368,8.341111952
0.291103467,8.34430244
0.291470133,8.346641586
0.2918368,8.349187217
0.292203467,8.352730358
0.292570133,8.355814988
0.2929368,8.357492105
0.293303467,8.359734413
0.293670133,8.362727973
0.2940368,8.366403952
0.294403467,8.368662336
0.294770133,8.371750907
0.2951368,8.374645799
0.295503467,8.377320155
0.295870133,8.380150029
0.2962368,8.382308382
0.296603467,8.385818942
0.296970133,8.387977756
0.2973368,8.391111687
0.297703467,8.394711161
0.298070133,8.396410226
0.2984368,8.399849893
0.298803467,8.40180708
0.299170133,8.405090801
0.2995368,8.407446549
0.299903467,8.410135485
0.300270133,8.412681235
0.3006368,8.416020289
0.301003467,8.418163892
0.301370133,8.421235109
0.3017368,8.424318473
0.302103467,8.426816821
0.302470133,8.428591709
0.3028368,8.432085835
0.303203467,8.434589789
0.303570133,8.437202964
0.3039368,8.440287664
0.304303467,8.442868355
0.304670133,8.445639831
0.3050368,8.448075588
0.305403467,8.450089007
0.305770133,8.453446104
0.3061368,8.456564448
0.306503467,8.457725346
0.306870133,8.460068139
0.3072368,8.462513598
0.307603467,8.465297318
0.307970133,8.46762107
0.3083368,8.470866907
0.308703467,8.472603452
0.309070133,8.475536672
0.3094368,8.478545956
0.309803467,8.480617269
0.310170133,8.48282627
0.3105368,8.485347684
0.310903467,8.488884669
0.311270133,8.490399902
0.3116368,8.494106691
0.312003467,8.495645226
0.312370133,8.498968998
0.3127368,8.499251471
0.313103467,8.502609889
0.313470133,8.504684298
0.3138368,8.50746319
0.314203467,8.509640698
0.314570133,8.511935125
0.3149368,8.514343245
0.315303467,8.516812691
0.315670133,8.519173764
0.3160368,8.522085461
0.316403467,8.5240174
0.316770133,8.526801775
0.3171368,8.529318477
0.317503467,8.530529801
0.317870133,8.533959535
0.3182368,8.535614026
0.318603467,8.537468501
0.318970133,8.541150686
0.3193368,8.543367305
0.319703467,8.545543542
0.320070133,8.54708528
0.3204368,8.55046641
0.320803467,8.552461069
0.321170133,8.555495528
0.3215368,8.558084674
0.321903467,8.559302454
0.322270133,8.561627577
0.3226368,8.564769198
0.323003467,8.566439999
0.323370133,8.569849831
0.3237368,8.570996782
0.324103467,8.573560906
0.324470133,8.575381893
0.3248368,8.578404733
0.325203467,8.581522388
0.325570133,8.584762154
0.3259368,8.586159894
0.326303467,8.588520667
0.326670133,8.590507697
0.3270368,8.594253752
0.327403467,8.595268914
0.327770133,8.597415166
0.3281368,8.601131265
0.328503467,8.602321598
0.328870133,8.606492009
0.3292368,8.608033449
0.329603467,8.610910891
0.329970133,8.613316937
0.3303368,8.615358301
0.330703467,8.6176393
0.331070133,8.619607059
0.3314368,8.622796766
0.331803467,8.625033093
0.332170133,8.627104384
0.3325368,8.629487224
0.332903467,8.630660897
0.333270133,8.633071434
0.3336368,8.636610939
0.334003467,8.63710242
0.334370133,8.640954495
0.3347368,8.64216311
0.335103467,8.644683219
0.335470133,8.646844652
0.3358368,8.648425892
0.336203467,8.651287452
0.336570133,8.652175527
0.3369368,8.655270049
0.337303467,8.658009366
0.337670133,8.659145125
0.3380368,8.661367361
0.338403467,8.66362687
0.338770133,8.667064275
0.3391368,8.668268735
0.339503467,8.670046767
0.339870133,8.673035527
0.3402368,8.674656824
0.340603467,8.677515642
0.340970133,8.678978665
0.3413368,8.680677019
0.341703467,8.684385543
0.342070133,8.684346275
0.3424368,8.688236615
0.342803467,8.690357348
0.343170133,8.691086844
0.3435368,8.694331698
0.343903467,8.695510821
0.344270133,8.697839601
0.3446368,8.700877329
0.345003467,8.701099496
0.345370133,8.704922535
0.3457368,8.706328444
0.346103467,8.708636284
0.346470133,8.709795135
0.3468368,8.712457225
0.347203467,8.715568367
0.347570133,8.716281195
0.3479368,8.719731424
0.348303467,8.721280769
0.348670133,8.722572079
0.3490368,8.726991045
0.349403467,8.727977219
0.349770133,8.730114755
0.3501368,8.731678491
0.350503467,8.73429459
0.350870133,8.735817364
0.3512368,8.738081765
0.351603467,8.740561429
0.351970133,8.742494613
0.3523368,8.744442027
0.352703467,8.747519914
0.353070133,8.748357689
0.3534368,8.751000932
0.353803467,8.753149404
0.354170133,8.75507063
0.3545368,8.757383893
0.354903467,8.758779846
0.355270133,8.762317381
0.3556368,8.764483469
0.356003467,8.76591317
0.356370133,8.769490375
0.3567368,8.770820827
0.357103467,8.772703439
0.357470133,8.775362363
0.3578368,8.777266572
0.358203467,8.780177377
0.358570133,8.781499882
0.3589368,8.783489548
0.359303467,8.78638077
0.359670133,8.788113849
0.3600368,8.788575774
0.360403467,8.791882674
0.360770133,8.79437699
0.3611368,8.795866273
0.361503467,8.797796194
0.361870133,8.800321255
0.3622368,8.80113493
0.362603467,8.803945972
0.362970133,8.806860162
0.3633368,8.807811658
0.363703467,8.810878747
0.364070133,8.81148117
0.3644368,8.814245189
0.364803467,8.815878
0.365170133,8.818680733
0.3655368,8.82156716
0.365903467,8.822634719
0.366270133,8.825232504
0.3666368,8.826902114
0.367003467,8.830151843
0.367370133,8.831461627
0.3677368,8.833796388
0.368103467,8.835598998
0.368470133,8.838966601
0.3688368,8.84135926
0.369203467,8.843585255
0.369570133,8.845104167
0.3699368,8.847672049
0.370303467,8.848997712
0.370670133,8.850508931
0.3710368,8.853127854
0.371403467,8.855840359
0.371770133,8.857714395
0.3721368,8.859784626
0.372503467,8.860843076
0.372870133,8.863919331
0.3732368,8.866209135
0.373603467,8.868128501
0.373970133,8.870719709
0.3743368,8.872289301
0.374703467,8.87392017
0.375070133,8.876359924
0.3754368,8.878166133
0.375803467,8.880793898
0.376170133,8.882319591
0.3765368,8.885216693
0.376903467,8.886795437
0.377270133,8.889293903
0.3776368,8.890542587
0.378003467,8.891754364
0.378370133,8.896120809
0.3787368,8.89590184
0.379103467,8.899507144
0.379470133,8.901675683
0.3798368,8.903407299
0.380203467,8.905377127
0.380570133,8.907024491
0.3809368,8.909169034
0.381303467,8.911382889
0.381670133,8.91335696
0.3820368,8.914974209
0.382403467,8.916895933
0.382770133,8.919167933
0.3831368,8.92055081
0.383503467,8.922441291
0.383870133,8.924803383
0.3842368,8.927627074
0.384603467,8.92928035
0.384970133,8.931228484
0.3853368,8.932490732
0.385703467,8.935259456
0.386070133,8.937914368
0.3864368,8.939246391
0.386803467,8.941989001
0.387170133,8.943089858
0.3875368,8.946024667
0.387903467,8.946753002
0.388270133,8.949732652
0.3886368,8.950843787
0.389003467,8.953075157
0.389370133,8.955458249
0.3897368,8.957951638
0.390103467,8.958930003
0.390470133,8.961637778
0.3908368,8.962519182
0.391203467,8.964948488
0.391570133,8.967365399
0.3919368,8.969473957
0.392303467,8.971720828
0.392670133,8.973557022
0.3930368,8.975475766
0.393403467,8.978010269
0.393770133,8.979640309
0.3941368,8.98165653
0.394503467,8.983431919
0.394870133,8.984618962
0.3952368,8.986796479
0.395603467,8.98875159
0.395970133,8.990511225
0.3963368,8.9917801
0.396703467,8.994291314
0.397070133,8.995780198
0.3974368,8.997772305
0.397803467,8.999932177
0.398170133,9.000867185
0.3985368,9.003843837
0.398903467,9.004497218
0.399270133,9.007272668
0.3996368,9.009002741
0.400003467,9.010969354
0.400370133,9.013043513
0.4007368,9.014227354
0.401103467,9.01721456
0.401470133,9.019454976
0.4018368,9.0200105
0.402203467,9.021762434
0.402570133,9.023910916
0.4029368,9.025784771
0.403303467,9.027410624
0.403670133,9.02983416
0.4040368,9.031244211
0.404403467,9.032384484
0.404770133,9.034740363
0.4051368,9.037207248
0.405503467,9.03732377
0.405870133,9.039841611
0.4062368,9.041706675
0.406603467,9.043418876
0.406970133,9.045040684
0.4073368,9.0456606
0.407703467,9.048385243
0.408070133,9.050264927
0.4084368,9.053131855
0.408803467,9.054514975
0.409170133,9.055771697
0.4095368,9.057252353
0.409903467,9.060169231
0.410270133,9.06214997
0.4106368,9.064496296
0.411003467,9.065625319
0.411370133,9.066970591
0.4117368,9.069021626
0.412103467,9.070519984
0.412470133,9.073848765
0.4128368,9.075158252
0.413203467,9.076528423
0.413570133,9.078390131
0.4139368,9.07952286
0.414303467,9.082562673
0.414670133,9.082661227
0.4150368,9.084718671
0.415403467,9.087112533
0.415770133,9.089063118
0.4161368,9.090061747
0.416503467,9.092677966
0.416870133,9.094457475
0.4172368,9.096146514
0.417603467,9.097832427
0.417970133,9.099250032
0.4183368,9.10167907
0.418703467,9.102946066
0.419070133,9.105445891
0.4194368,9.106311462
0.419803467,9.107796756
0.420170133,9.110188185
0.4205368,9.112051344
0.420903467,9.112873052
0.421270133,9.114535612
0.4216368,9.116655103
0.422003467,9.119281397
0.422370133,9.120228483
0.4227368,9.121859797
0.423103467,9.124682164
0.423470133,9.125241488
0.4238368,9.127058828
0.424203467,9.128954352
0.424570133,9.131223921
0.4249368,9.131984375
0.425303467,9.134715958
0.425670133,9.136670334
0.4260368,9.137724145
0.426403467,9.139973857
0.426770133,9.141106241
0.4271368,9.143326854
0.427503467,9.14530375
0.427870133,9.147596971
0.4282368,9.149146012
0.428603467,9.150852963
0.428970133,9.15358598
0.4293368,9.155189995
0.429703467,9.156937405
0.430070133,9.15905443
0.4304368,9.161312284
0.430803467,9.162671727
0.431170133,9.164103872
0.4315368,9.166477468
0.431903467,9.167645016
0.432270133,9.170294419
0.4326368,9.17165386
0.433003467,9.174305591
0.433370133,9.175474629
0.4337368,9.178104652
0.434103467,9.178455572
0.434470133,9.180400017
0.4348368,9.182916173
0.435203467,9.185296992
0.435570133,9.186849029
0.4359368,9.187517527
0.436303467,9.190644082
0.436670133,9.191834139
0.4370368,9.193899874
0.437403467,9.195433619
0.437770133,9.19712743
0.4381368,9.198560391
0.438503467,9.200627486
0.438870133,9.202920465
0.4392368,9.204791132
0.439603467,9.206313737
0.439970133,9.208156335
0.4403368,9.208893804
0.440703467,9.210705727
0.441070133,9.212817755
0.4414368,9.214743055
0.441803467,9.217425416
0.442170133,9.21864469
0.4425368,9.220047222
0.442903467,9.222392317
0.443270133,9.223055772
0.4436368,9.226499049
0.444003467,9.22701958
0.444370133,9.228062597
0.4447368,9.229272372
0.445103467,9.232422474
0.445470133,9.233514627
0.4458368,9.236240638
0.446203467,9.238072409
0.446570133,9.238800278
0.4469368,9.240989408
0.447303467,9.241986222
0.447670133,9.243654655
0.4480368,9.24530319
0.448403467,9.246434791
0.448770133,9.248691204
0.4491368,9.251468701
0.449503467,9.251622515
0.449870133,9.253551594
0.4502368,9.25548408
0.450603467,9.255976232
0.450970133,9.259484933
0.4513368,9.259500862
0.451703467,9.261011141
0.452070133,9.262887709
0.4524368,9.264112924
0.452803467,9.266792825
0.453170133,9.267673818
0.4535368,9.270058444
0.453903467,9.270853158
0.454270133,9.271762895
0.4546368,9.273435316
0.455003467,9.275584868
0.455370133,9.27711097
0.4557368,9.277977958
0.456103467,9.27880037
0.456470133,9.281146468
0.4568368,9.283100651
0.457203467,9.284149659
0.457570133,9.286631076
0.4579368,9.286358542
0.458303467,9.288871492
0.458670133,9.291067156
0.4590368,9.291375302
0.459403467,9.293089331
0.459770133,9.295004017
0.4601368,9.29702798
0.460503467,9.297436589
0.460870133,9.299941407
0.4612368,9.301759536
0.461603467,9.303037172
0.461970133,9.305172458
0.4623368,9.306183696
0.462703467,9.307695268
0.463070133,9.309605837
0.4634368,9.310349471
0.463803467,9.312221022
0.464170133,9.314246472
0.4645368,9.316003263
0.464903467,9.31805406
0.465270133,9.318369448
0.4656368,9.320391958
0.466003467,9.321688932
0.466370133,9.323402051
0.4667368,9.325662755
0.467103467,9.326175348
0.467470133,9.328585969
0.4678368,9.329482777
0.468203467,9.330740921
0.468570133,9.33252199
0.4689368,9.33406391
0.469303467,9.335560409
0.469670133,9.337340188
0.4700368,9.338450633
0.470403467,9.339861596
0.470770133,9.340730688
0.4711368,9.343258964
0.471503467,9.344147366
0.471870133,9.34626619
0.4722368,9.348452385
0.472603467,9.348751487
0.472970133,9.350605688
0.4733368,9.3519228
0.473703467,9.354623458
0.474070133,9.35620436
0.4744368,9.356624544
0.474803467,9.357943639
0.475170133,9.359557621
0.4755368,9.360625782
0.475903467,9.362235965
0.476270133,9.363893558
0.4766368,9.365772006
0.477003467,9.365993648
0.477370133,9.367778384
0.4777368,9.369658865
0.478103467,9.371032524
0.478470133,9.372836811
0.4788368,9.373814337
0.479203467,9.376741454
0.479570133,9.377157397
0.4799368,9.378785078
0.480303467,9.381086036
0.480670133,9.382308462
0.4810368,9.383709232
0.481403467,9.384638426
0.481770133,9.386534421
0.4821368,9.388636802
0.482503467,9.389161198
0.482870133,9.391045133
0.4832368,9.393438595
0.483603467,9.393112414
0.483970133,9.395543193
0.4843368,9.396832984
0.484703467,9.398160758
0.485070133,9.400333325
0.4854368,9.401539221
0.485803467,9.402879072
0.486170133,9.404245531
0.4865368,9.406883375
0.486903467,9.408036182
0.487270133,9.408863149
0.4876368,9.412381668
0.488003467,9.4118722
0.488370133,9.414031487
0.4887368,9.41601897
0.489103467,9.41723197
0.489470133,9.420111207
0.4898368,9.420914062
0.490203467,9.4214913
0.490570133,9.423805741
0.4909368,9.424439844
0.491303467,9.426652536
0.491670133,9.428343248
0.4920368,9.429903697
0.492403467,9.431884078
0.492770133,9.433340859
0.4931368,9.435144067
0.493503467,9.436599118
0.493870133,9.438080149
0.4942368,9.440065777
0.494603467,9.440220553
0.494970133,9.442696964
0.4953368,9.443129949
0.495703467,9.445519
0.496070133,9.446818299
0.4964368,9.448363671
0.496803467,9.450587019
0.497170133,9.451548475
0.4975368,9.452235781
0.497903467,9.454401372
0.498270133,9.455027064
0.4986368,9.455860146
0.499003467,9.457935948
0.499370133,9.458016518
0.4997368,9.46089154
0.499970133,9.460999018